<?xml version="1.0"?>
<robot name="omnipointer">
  <!--MX64trntbl
  + MX106:  ? + 0.153 -->
  <!-- singleaxismount + 2.5girder + singleaxismount + base + MX106: 0.007370876 + 0.0226796 +
  0.007370876 + ? + 0.153 -->
  <!-- frame106 + singleaxismount + adjustgirder + singleaxismount + base + MX28: 0.0907185 +
  0.00737088 + 0.110563 + 0.00737088 + ? + 0.077 -->
  <!-- frame28 + singleaxismount + 5girder + singleaxismount + base + MX28: 0.0907185 + 0.00737088 +
  0.0368544 + 0.00737088 + ? + 0.077 -->
  <!-- frame28 + singleaxismount + 2.5girder + singleaxismount + tip: 0.0907185 + 0.00737088 +
  0.0226796 + 0.00737088 + ? -->
  <material name="omni/Blue">
    <color rgba="0 0 0.8 1" />
  </material>
  <material name="omni/Red">
    <color rgba="1 0 0 1" />
  </material>
  <material name="omni/Green">
    <color rgba="0 1 0 1" />
  </material>
  <material name="omni/Yellow">
    <color rgba="1 1 0 1" />
  </material>
  <material name="omni/LightGrey">
    <color rgba="0.6 0.6 0.6 1" />
  </material>
  <material name="omni/DarkGrey">
    <color rgba="0.4 0.4 0.4 1" />
  </material>

  <!-- <link name="control_link">
  </link>
  
  <joint type="fixed">
    <parent link="base_link"/>
    <child link="control_link"/>
    <origin rpy="0 0 3.14" xyz=" 0 0 0"/>
  </joint> -->


  <!-- foot for arm-->
  <link name="base_link">
    <inertial>
      <origin rpy="0 0 0" xyz="0 0 0" />
      <mass value="10.0" />
      <inertia ixx="0.1" ixy="0" ixz="0" iyy="0.1" iyz="0" izz="0.1" />
    </inertial>
  </link>
  <!-- joint between base_link and arm_0_link -->
  <joint name="arm_joint_0" type="fixed">
    <origin rpy="0 0 3.1415" xyz="0 0 0" />
    <parent link="base_link" />
    <child link="arm_link_0" />
  </joint>


  <link name="arm_link_0">
    <visual>
      <origin rpy="0 0 0" xyz="0 0 0.02725" />
      <geometry>
        <box size="0.1143 0.1143 0.0600" />
      </geometry>
      <material name="omni/LightGrey" />
    </visual>
    <visual>
      <origin rpy="0 0 0" xyz="0 0 0.0600" />
      <geometry>
        <cylinder radius="0.04" length="0.01" />
      </geometry>
      <material name="omni/LightGrey" />
    </visual>

    <collision>
      <origin rpy="0 0 0" xyz="0 0 0.02725" />
      <geometry>
        <box size="0.1143 0.1143 0.0600" />
      </geometry>
    </collision>
    <inertial>
      <!-- CENTER OF MASS -->
      <origin rpy="0 0 0" xyz="0 0 0.02725" />
      <mass value="0.2" />
      <!-- box inertia: 1/12*m(y^2+z^2), ... -->
      <inertia ixx="0.000267245666667" ixy="0" ixz="0" iyy="0.000267245666667" iyz="0"
        izz="0.000435483" />
    </inertial>
  </link>


  <joint name="arm_joint_1" type="revolute">
    <parent link="arm_link_0" />
    <child link="arm_link_1" />
    <limit effort="5.0" lower="-3.1415926535" upper="3.1415926535" velocity="5.0" />
    <origin rpy="0 0 0.0" xyz="0 0 0.0600" />
    <axis xyz="0 0 1" />
    <dynamics damping="0.5" />
  </joint>


  <link name="arm_link_1">
    <visual>
      <origin rpy="0 0 0" xyz="0 0 0.0615" />
      <geometry>
        <box size="0.0402 0.05 0.115" />
      </geometry>
      <material name="omni/Blue" />
    </visual>

    <visual>
      <origin rpy="1.57 0 0" xyz="0 0 0.115" />
      <geometry>
        <cylinder radius="0.025" length="0.054" />
      </geometry>
      <material name="omni/Blue" />
    </visual>

    <collision>
      <origin rpy="0 0 0" xyz="0 0 0.0615" />
      <geometry>
        <box size="0.0402 0.05 0.115" />
      </geometry>
    </collision>

    <inertial>
      <!-- CENTER OF MASS -->
      <origin rpy="0 0 0" xyz="0 0 0.115" />
      <mass value="0.190421352" />
      <!-- box inertia: 1/12*m(y^2+z^2), ... -->
      <inertia ixx="0.000279744834534" ixy="0" ixz="0" iyy="0.000265717763008" iyz="0"
        izz="6.53151584738e-05" />
    </inertial>
  </link>


  <joint name="arm_joint_2" type="revolute">
    <parent link="arm_link_1" />
    <child link="arm_link_2" />
    <limit effort="5.0" lower="-1.57079632679" upper="1.57079632679" velocity="5.0" />
    <origin rpy="0 0.0 0" xyz="0 0 0.115" />
    <axis xyz="0 1 0" />
    <dynamics damping="0.5" />
  </joint>


  <link name="arm_link_2">
    <visual>
      <origin rpy="0 0 0" xyz="0 0 0.09375" />
      <geometry>
        <box size="0.0356 0.05 0.2060" />
      </geometry>
      <material name="omni/Red" />
    </visual>
    <visual>
      <origin rpy="1.57 0 0" xyz="0.02 0 0.2060" />
      <geometry>
        <cylinder radius="0.025" length="0.05" />
      </geometry>
      <material name="omni/Red" />
    </visual>


    <collision>
      <origin rpy="0 0 0" xyz="0 0 0.09375" />
      <geometry>
        <box size="0.0356 0.05  0.2060" />
      </geometry>
    </collision>
    <inertial>
      <!-- CENTER OF MASS -->
      <origin rpy="0 0 0" xyz="0 0 0.9375" />
      <mass value="0.29302326" />
      <!-- box inertia: 1/12*m(y^2+z^2), ... -->
      <inertia ixx="0.00251484771035" ixy="0" ixz="0" iyy="0.00248474836108" iyz="0"
        izz="9.19936757328e-05" />
    </inertial>
  </link>


  <joint name="arm_joint_3" type="revolute">
    <parent link="arm_link_2" />
    <child link="arm_link_3" />
    <limit effort="5.0" lower="-1.57079632679" upper="1.57079632679" velocity="5.0" />
    <origin rpy="0 1.57 0" xyz="0.0250 0 0.2050" />
    <axis xyz="0 1 0" />
    <dynamics damping="0.5" />
  </joint>


  <link name="arm_link_3">
    <visual>
      <origin rpy="0 0 0" xyz="0 0 0.0950" />
      <geometry>
        <box size="0.0356 0.05 0.198" />
      </geometry>
      <material name="omni/Yellow" />
    </visual>

    <visual>
      <origin rpy="0 0 0" xyz="0 0 0.198" />
      <geometry>
        <cylinder radius="0.0402" length="0.01" />
      </geometry>
      <material name="omni/Yellow" />
    </visual>

    <collision>
      <origin rpy="0 0 0" xyz="0 0 0.0825" />
      <geometry>
        <box size="0.0356 0.05 0.200" />
      </geometry>
    </collision>
    <inertial>
      <!-- CENTER OF MASS -->
      <origin rpy="0 0 0" xyz="0 0 0.0825" />
      <mass value="0.21931466" />
      <!-- box inertia: 1/12*m(y^2+z^2), ... -->
      <inertia ixx="0.000791433503053" ixy="0" ixz="0" iyy="0.000768905501178" iyz="0"
        izz="6.88531064581e-05" />
    </inertial>
  </link>

  <joint name="arm_joint_4" type="revolute">
    <parent link="arm_link_3" />
    <child link="arm_link_4" />
    <limit effort="5.0" lower="-1.57079632679" upper="1.57079632679" velocity="5.0" />
    <origin rpy="0 0 0.0" xyz="0 0 0.200" />
    <axis xyz="0 0 1" />
    <dynamics damping="0.5" />
  </joint>


  <link name="arm_link_4">
    <visual>
      <origin rpy="0 0 0" xyz="0 0 0.01" />
      <geometry>
        <box size="0.0356 0.05 0.03" />
      </geometry>
      <material name="omni/Green" />
    </visual>

    <visual>
      <origin rpy="1.57 0 0" xyz="0 0 0.04" />
      <geometry>
        <cylinder radius="0.025" length="0.05" />
      </geometry>
      <material name="omni/Green" />
    </visual>

    <collision>
      <origin rpy="0 0 0" xyz="0 0 0.04" />
      <geometry>
        <box size="0.0356 0.05 0.03" />
      </geometry>
    </collision>
    <inertial>
      <!-- CENTER OF MASS -->
      <origin rpy="0 0 0" xyz="0 0 0.08025" />
      <mass value="0.15813986" />
      <!-- box inertia: 1/12*m(y^2+z^2), ... -->
      <inertia ixx="0.00037242266488" ixy="0" ixz="0" iyy="0.000356178538461" iyz="0"
        izz="4.96474819141e-05" />
    </inertial>
  </link>

  <joint name="arm_joint_5" type="revolute">
    <parent link="arm_link_4" />
    <child link="arm_link_5" />
    <origin rpy="0 1.57 0" xyz="0 0 0.045" />
    <axis xyz="0 1 0" />
    <limit effort="5.0" lower="-1.57079632679" upper="1.57079632679" velocity="5.0" />

  </joint>


  <link name="arm_link_5">
    <visual>
      <origin rpy="0 0 0" xyz="0 0 0.0225" />
      <geometry>
        <box size="0.0356 0.05 0.045" />
      </geometry>
      <material name="omni/Red" />
    </visual>

    <visual>
      <origin rpy="0 0 0" xyz="0 0 0.045" />
      <geometry>
        <cylinder radius="0.0402" length="0.01" />
      </geometry>
      <material name="omni/Red" />
    </visual>

    <collision>
      <origin rpy="0 0 0" xyz="0 0 0.0225" />
      <geometry>
        <box size="0.0356 0.05 0.045" />
      </geometry>
    </collision>
    <inertial>
      <!-- CENTER OF MASS -->
      <origin rpy="0 0 0" xyz="0 0 0.08" />
      <mass value="0.15813986" />
      <!-- box inertia: 1/12*m(y^2+z^2), ... -->
      <inertia ixx="0.00037242266488" ixy="0" ixz="0" iyy="0.000356178538461" iyz="0"
        izz="4.96474819141e-05" />
    </inertial>
  </link>


  <joint name="arm_joint_6" type="revolute">
    <parent link="arm_link_5" />
    <child link="arm_link_6" />
    <origin rpy="0 0 0.0" xyz="0 0 0.045" />
    <axis xyz="0 0 1" />
    <limit effort="5.0" lower="-1.57079632679" upper="1.57079632679" velocity="5.0" />

  </joint>


  <link name="arm_link_6">
    <visual>
      <origin rpy="0 0 0" xyz="0 0 0.0575" />
      <geometry>
        <box size="0.0356 0.05 0.115" />
      </geometry>
      <material name="omni/Blue" />
    </visual>
    <collision>
      <origin rpy="0 0 0" xyz="0 0 0.0575" />
      <geometry>
        <box size="0.0356 0.05 0.115" />
      </geometry>
    </collision>
    <inertial>
      <!-- CENTER OF MASS -->
      <origin rpy="0 0 0" xyz="0 0 0.08025" />
      <mass value="0.15813986" />
      <!-- box inertia: 1/12*m(y^2+z^2), ... -->
      <inertia ixx="0.00037242266488" ixy="0" ixz="0" iyy="0.000356178538461" iyz="0"
        izz="4.96474819141e-05" />
    </inertial>
  </link>


  <joint name="arm_joint_7" type="fixed">
    <parent link="arm_link_6" />
    <child link="tip" />
    <!-- origin rpy="3.14 0 0" xyz="0 0 0.04" / -->
    <origin rpy="3.1415 0. 0." xyz="0 0 0.04"/>
    <axis xyz="0 1 0" />
  </joint>


  <link name="tip">
    <visual>
      <origin rpy="0 0 0" xyz="0 0 0.0" />
      <geometry>
        <sphere radius="0.04" />
      </geometry>
      <material name="omni/Yellow" />
    </visual>
    <collision>
      <origin rpy="0 0 0" xyz="0 0 0.0" />
      <geometry>
        <sphere radius="0.01" />
      </geometry>
    </collision>
    <inertial>
      <!-- CENTER OF MASS -->
      <origin rpy="0 0 0" xyz="0 0 0.08025" />
      <mass value="0.15813986" />
      <!-- box inertia: 1/12*m(y^2+z^2), ... -->
      <inertia ixx="0.00037242266488" ixy="0" ixz="0" iyy="0.000356178538461" iyz="0"
        izz="4.96474819141e-05" />
    </inertial>
  </link>

  <!-- END OF ARM LINKS/JOINTS -->
</robot>